Workbook
Name hsdiariasdisponibles: 'Sprint1 '!$AM$81
Name OLE_LINK1: Resumen!$B$2
Name recursos1: 'Sprint1 '!$AK$67:$AN$80
Name recursos2: 'Sprint1 '!$AK$68:$AN$80

Sheet BackLog
E2: CÓDIGO
C3: Plan de Iteración | E3: F-PE-CYMP-007-005
E4: VERSIÓN: 1.0.0
A6: Área de Proyectos
A7: Elaboró: | C7: Aprobó: | E7: Revisó: FMO
A8: METODOS AGILES SCRUM
A9: BackLog Product
A10: Cargar Requerimientos del cliente , Riesgo , Valor para el Cliente y Sprint donde se realizará
A12: Requerimiento | B12: Link Especificación | C12: Estimado | D12: Riesgo | E12: Factor | F12: Esfuerzo Restante | G12: Valor | H12: Indicador de Valor | I12: Spring
A14: Pases | D14: Sin Riesgo | F14: =+'Sprint1 '!D28 -> 11 | G14: Relevante
A15: Dietas | C15: 11.70989 | D15: Sin Riesgo | F15: =+'Sprint1 '!D29 -> 0 | G15: Relevante | H15: =VLOOKUP(G15,$N$17:$O$27,2,0) -> 300 | I15: 2
A16: Asignacion de Dietas | D16: Sin Riesgo | F16: =+'Sprint1 '!D30 -> 9 | G16: Relevante | H16: =VLOOKUP(G16,$N$17:$O$27,2,0) -> 300 | I16: 2 | N16: Valor Tarea: Otorgado por el Cliente | R16: Riesgo
A17: Informe de Dietas | D17: Sin Riesgo | F17: =+'Sprint1 '!D31 -> 3 | G17: Relevante | H17: =VLOOKUP(G17,$N$17:$O$27,2,0) -> 300 | I17: 2 | N17: No Relevante | O17: 100 | R17: Sin Riesgo | S17: 0
A18: Valoraciones Iniciales | D18: Sin Riesgo | F18: =+'Sprint1 '!D32 -> 0 | G18: Relevante | H18: =VLOOKUP(G18,$N$17:$O$27,2,0) -> 300 | N18: Normal | O18: 200 | R18: Muy Bajo | S18: 0.1
A19: Valoraciones Iniciales | D19: Sin Riesgo | F19: =+'Sprint1 '!D33 -> 0 | G19: Relevante | H19: =VLOOKUP(G19,$N$17:$O$27,2,0) -> 300 | I19: 2 | N19: Relevante | O19: 300 | R19: Bajo | S19: 0.2
A20: Expediente Personal Clínico Social | D20: Sin Riesgo | F20: =+'Sprint1 '!D34 -> 0 | G20: Normal | H20: =VLOOKUP(G20,$N$17:$O$27,2,0) -> 200 | N20: Deseable | O20: 400 | R20: Medio | S20: 0.4
A21: Expediente Personal Clínico Social | C21: 11.70989 | D21: Sin Riesgo | F21: =+'Sprint1 '!D35 -> 0 | G21: Relevante | H21: =VLOOKUP(G21,$N$17:$O$27,2,0) -> 300 | I21: 1 | N21: Indispensable | O21: 500 | R21: Alto | S21: 0.6
A22: Arbol de centros | C22: 29.274725 | D22: Sin Riesgo | F22: =+'Sprint1 '!D36 -> 0 | G22: Relevante | H22: =VLOOKUP(G22,$N$17:$O$27,2,0) -> 300 | I22: 1
A23: Listado de residentes | C23: 11.70989 | D23: Sin Riesgo | F23: =+'Sprint1 '!D37 -> 0 | G23: Relevante | H23: =VLOOKUP(G23,$N$17:$O$27,2,0) -> 300 | I23: 1
A24: Información general | C24: 11.70989 | D24: Sin Riesgo | F24: =+'Sprint1 '!D38 -> 0 | G24: Relevante | I24: 1
A25: Visión General | C25: 29.274725 | D25: Sin Riesgo | F25: =+'Sprint1 '!D39 -> 0 | G25: Relevante | I25: 1
A26: Caidas | C26: 29.274725 | D26: Sin Riesgo | F26: =+'Sprint1 '!D40 -> 10 | G26: Relevante | I26: 1
A27: Incidencas | C27: 13.173626 | I27: 1
A28: Generales | C28: 4.3912088 | D28: Sin Riesgo | F28: =+'Sprint1 '!D42 -> 0 | G28: Relevante | I28: 1
A29: Tareas | C29: 4.3912088 | D29: Sin Riesgo | F29: =+'Sprint1 '!D43 -> 0 | G29: Normal | I29: 1
A30: Alertas Medicación | C30: 4.3912088 | D30: Sin Riesgo | F30: =+'Sprint1 '!D44 -> 11 | G30: Normal | I30: 1
A31: Visitas | C31: 29.274725 | D31: Sin Riesgo | F31: =+'Sprint1 '!D45 -> 0 | G31: Normal | I31: 1
A32: Dietas (reutilización) | I32: 2
A33: Médico | C33: 11.70989 | D33: Sin Riesgo | F33: =+'Sprint1 '!D47 -> 0 | G33: Relevante | I33: 1
A34: Anámnesis | C34: 29.274725 | D34: Sin Riesgo | F34: =+'Sprint1 '!D48 -> 0 | G34: Normal | I34: 1
A35: Valoracion Inicial | I35: 2
A36: Diagnosis | C36: 52.694505 | D36: Sin Riesgo | F36: =+'Sprint1 '!D50 -> 0 | G36: Relevante | I36: 2
A37: Dietas (reutilización) | D37: Sin Riesgo | F37: =+'Sprint1 '!D51 -> 5 | G37: Normal | I37: 2
A38: Tratamiento Medicamentoso | C38: 52.694505 | I38: 2
A39: Exploracion Fisica | C39: 29.274725 | D39: Sin Riesgo | F39: =+'Sprint1 '!D53 -> 10 | G39: Normal | I39: 2
A40: Analitica | I40: 2
A41: Ordenes | C41: 29.274725 | D41: Sin Riesgo | F41: =+'Sprint1 '!D63 -> 4.5507692 | G41: Normal | I41: 2
A42: Seguimiento Evolutivo | C42: 29.274725 | D42: Sin Riesgo | F42: =+'Sprint1 '!D64 -> 0 | G42: Normal | I42: 2
A43: Valoraciones Seguimiento | D43: Sin Riesgo | F43: =+'Sprint1 '!D65 -> 0 | G43: Normal | I43: 2
A44: Emfermeria | C44: 29.274725 | D44: Sin Riesgo | F44: =+'Sprint1 '!D66 -> 0 | G44: Normal | I44: 3
...

Sheet BackLog Riegos 
E2: CÓDIGO
C3: Plan de Iteración | E3: F-PE-CYMP-007-005
E4: VERSIÓN: 1.0.0 Beta
A6: Área de Proyectos
A7: Elaboró: | C7: Aprobó: | E7: Revisó: FMO | F7: Revisó:
A9: METODOS AGILES SCRUM
A10: BackLog Riegos
A11: Cargar Requerimientos nuevos y riegos , problemas
A13: Dia | B13: Riego | C13: Observaciones | D13: Resolucion | E13: Estimado | F13: Riesgo | G13: Factor | H13: Esfuerzo Restante | I13: Valor | J13: Indicador de Valor | K13: Spring
A14: 39793 | B14: Faltan ejemplos reales de implemetacion de I8N por vitae | C14: nos faltaria ejemplo real de pantallas a desarrollar por Vitae para que no nos impacten cambios de arquitectura, el modelo enviado no es muy claro el uso | D14: pendiente | F14: Bajo | I14: Normal | K14: anterior
P16: Valor Tarea: Otorgado por el Cliente | T16: Riesgo
P17: No Relevante | Q17: 100 | T17: Sin Riesgo | U17: 0
P18: Normal | Q18: 200 | T18: Muy Bajo | U18: 0.1
P19: Relevante | Q19: 300 | T19: Bajo | U19: 0.2
P20: Deseable | Q20: 400 | T20: Medio | U20: 0.4
F21: Sin Riesgo | I21: Normal | P21: Indispensable | Q21: 500 | T21: Alto | U21: 0.6
F22: Sin Riesgo | I22: Normal
F23: Sin Riesgo | I23: Normal

Sheet Resumen Sprints
E2: CÓDIGO
C3: Plan de Iteración | E3: F-PE-CYMP-007-005
E4: VERSIÓN: 1.0.0 Beta
A6: Área de Proyectos
A7: Elaboró: | C7: Aprobó: | E7: Revisó:
A8: METODOS AGILES SCRUM
C9: DIA HOY; | I9: =+NOW() -> 40072.48
A10: Resumen Sprint 2
A11: Cargar Tareas por Sprint, Estimado , Riego, solo para inicio srum cargar dia 2 y 3 Y CARGAS MANAULES EN ROJO
A12: Cargas la Fila Fecha con los dias reales sin sabados ni domingos ni feriados
A13: Titulo Importante | B13: Estimado | C13: Riesgo | D13: Factor | E13: Esfuerzo Restante | F13: Valor | G13: Indicador de Valor | H13: Ajustado | I13: Trabajo Pendiente
H14: D. Lab. | I14: 1 | J14: =+I14+1 -> 2 | K14: =+J14+1 -> 3 | L14: =+K14+1 -> 4 | M14: =+L14+1 -> 5 | N14: =+M14+1 -> 6 | O14: =+N14+1 -> 7 | P14: =+O14+1 -> 8 | Q14: =+P14+1 -> 9 | ... AC14: =+AB14+1 -> 21
B15: 430 HS | H15: Fecha | I15: 39861 | J15: 39862 | K15: 39863 | L15: 39864 | M15: 39865 | N15: 39867 | O15: 39868 | P15: 39869 | Q15: 39870 | R15: 39871 | S15: 39874 | T15: 39875 | U15: 39876 | V15: 39877 | W15: 39878 | X15: 39881 | Y15: 39882 | Z15: 39883 | AA15: 39885 | AB15: 39886 | AC15: 39887
H16: D. Sem. | I16: =WEEKDAY(I15,2) -> 2 | J16: =WEEKDAY(J15,2) -> 3 | K16: =WEEKDAY(K15,2) -> 4 | L16: =WEEKDAY(L15,2) -> 5 | M16: =WEEKDAY(M15,2) -> 6 | N16: =WEEKDAY(N15,2) -> 1 | O16: =WEEKDAY(O15,2) -> 2 | P16: =WEEKDAY(P15,2) -> 3 | ... Z16: =WEEKDAY(Z15,2) -> 3
H17: =SUM(H18:H23)+H24+H38+H47 -> 363.46192 | I17: =SUM(I18:I23)+I24+I38+I47 -> 363.46192 | J17: =SUM(J18:J23)+J24+J38+J47 -> 359.36038 | K17: =SUM(K18:K23)+K24+K38+K47 -> 340.10577 | L17: =SUM(L18:L23)+L24+L38+L47 -> 313.10577 | M17: =SUM(M18:M23)+M24+M38+M47 -> 318.555 | N17: =SUM(N18:N23)+N24+N38+N47 -> 273.80115 | O17: =SUM(O18:O23)+O24+O38+O47 -> 120.55077 | ... AC17: =SUM(AC18:AC23)+AC24+AC38+AC47 -> 120.55077
A18: Inicio Scrum | E18: =MIN(I18:Z18) -> 5 | H18: =SUM(H19:H23) -> 5 | I18: =SUM(I19:I23) -> 5 | J18: =SUM(J19:J23) -> 5 | K18: =SUM(K19:K23) -> 5 | L18: =SUM(L19:L23) -> 5 | M18: =SUM(M19:M23) -> 5 | N18: =SUM(N19:N23) -> 5 | O18: =SUM(O19:O23) -> 5 | ... AC18: =SUM(AC19:AC23) -> 5
A19: Planillas nuevo proyecto | B19: 1 | C19: Sin Riesgo | D19: =VLOOKUP(C19,$AQ$59:$AR$67,2,0) -> 0 | E19: 2 | H19: =+D19*B19+B19 -> 1 | I19: =+H19 -> 1 | J19: =+I19 -> 1 | K19: =+J19 -> 1 | L19: =+K19 -> 1 | M19: =+L19 -> 1 | N19: =+M19 -> 1 | O19: =+N19 -> 1 | P19: =+O19 -> 1 | ... AC19: =+AB19 -> 1
A20: Template BackLog | B20: 1 | C20: Sin Riesgo | D20: =VLOOKUP(C20,$AQ$59:$AR$67,2,0) -> 0 | E20: 1 | H20: =+D20*B20+B20 -> 1 | I20: =+H20 -> 1 | J20: =+I20 -> 1 | K20: =+J20 -> 1 | L20: =+K20 -> 1 | M20: =+L20 -> 1 | N20: =+M20 -> 1 | O20: =+N20 -> 1 | P20: =+O20 -> 1 | ... AC20: =+AB20 -> 1
A21: Crear backlog product | B21: 1 | C21: Sin Riesgo | D21: =VLOOKUP(C21,$AQ$59:$AR$67,2,0) -> 0 | E21: 1 | H21: =+D21*B21+B21 -> 1 | I21: =+H21 -> 1 | J21: =+I21 -> 1 | K21: =+J21 -> 1 | L21: =+K21 -> 1 | M21: =+L21 -> 1 | N21: =+M21 -> 1 | O21: =+N21 -> 1 | P21: =+O21 -> 1 | ... AC21: =+AB21 -> 1
A22: Crear Sprint backlog product | B22: 1 | C22: Sin Riesgo | D22: =VLOOKUP(C22,$AQ$59:$AR$67,2,0) -> 0 | E22: 1 | H22: =+D22*B22+B22 -> 1 | I22: =+H22 -> 1 | J22: =+I22 -> 1 | K22: =+J22 -> 1 | L22: =+K22 -> 1 | M22: =+L22 -> 1 | N22: =+M22 -> 1 | O22: =+N22 -> 1 | P22: =+O22 -> 1 | ... AC22: =+AB22 -> 1
A23: Plan de Release y Sprint | B23: 1 | C23: Sin Riesgo | D23: =VLOOKUP(C23,$AQ$59:$AR$67,2,0) -> 0 | E23: 1 | H23: =+D23*B23+B23 -> 1 | I23: =+H23 -> 1 | J23: =+I23 -> 1 | K23: =+J23 -> 1 | L23: =+K23 -> 1 | M23: =+L23 -> 1 | N23: =+M23 -> 1 | O23: =+N23 -> 1 | P23: =+O23 -> 1 | ... AC23: =+AB23 -> 1
A24: Sprint 1 | B24: =SUM(B25:B57) -> 314.98346 | E24: =+Z24 -> 100.55077 | G24: =SUM(G25:G51) -> #N/A | H24: =SUM(H25:H57) -> 322.98346 | I24: =SUM(I25:I57) -> 322.98346 | J24: =SUM(J25:J57) -> 318.88192 | K24: =SUM(K25:K57) -> 300.10577 | L24: =SUM(L25:L57) -> 273.10577 | M24: =SUM(M25:M57) -> 278.555 | N24: =SUM(N25:N57) -> 248.80115 | O24: =SUM(O25:O57) -> 100.55077 | ... AC24: =SUM(AC25:AC57) -> 100.55077
A25: Expediente Personal Clínico Social | B25: 4.5507692 | C25: Sin Riesgo | D25: =VLOOKUP(C25,$AQ$59:$AR$64,2,0) -> 0 | E25: =+Z25 -> 0 | G25: =VLOOKUP(F25,$AN$59:$AO$70,2,0) -> #N/A | H25: =+D25*B25+B25 -> 4.5507692 | I25: =+H25 -> 4.5507692 | J25: =+'Sprint1 '!G27 -> 0 | K25: =+'Sprint1 '!H27 -> 0 | L25: =+'Sprint1 '!I27 -> 0 | M25: =+'Sprint1 '!J27 -> 0 | N25: =+'Sprint1 '!K27 -> 0 | O25: =+'Sprint1 '!L27 -> 0 | P25: =+'Sprint1 '!M27 -> 0 | Q25: =+'Sprint1 '!N27 -> 0 | ... AC25: =+'Sprint1 '!Z27 -> 0
A26: Arbol de centros | B26: 11.376923 | C26: Sin Riesgo | D26: =VLOOKUP(C26,$AQ$59:$AR$64,2,0) -> 0 | E26: =+Z26 -> 11 | G26: =VLOOKUP(F26,$AN$59:$AO$70,2,0) -> #N/A | H26: =+D26*B26+B26 -> 11.376923 | I26: =+H26 -> 11.376923 | J26: =+'Sprint1 '!G28 -> 11.376923 | K26: =+'Sprint1 '!H28 -> 11 | L26: =+'Sprint1 '!I28 -> 11 | M26: =+'Sprint1 '!J28 -> 11 | N26: =+'Sprint1 '!K28 -> 11 | O26: =+'Sprint1 '!L28 -> 11 | P26: =+'Sprint1 '!M28 -> 11 | Q26: =+'Sprint1 '!N28 -> 11 | ... AC26: =+'Sprint1 '!Z28 -> 11
A27: Listado de residentes | B27: 4.5507692 | C27: Sin Riesgo | D27: =VLOOKUP(C27,$AQ$59:$AR$64,2,0) -> 0 | E27: =+Z27 -> 0 | G27: =VLOOKUP(F27,$AN$59:$AO$70,2,0) -> #N/A | H27: =+D27*B27+B27 -> 4.5507692 | I27: =+H27 -> 4.5507692 | J27: =+'Sprint1 '!G29 -> 4.5507692 | K27: =+'Sprint1 '!H29 -> 0 | L27: =+'Sprint1 '!I29 -> 0 | M27: =+'Sprint1 '!J29 -> 0 | N27: =+'Sprint1 '!K29 -> 0 | O27: =+'Sprint1 '!L29 -> 0 | P27: =+'Sprint1 '!M29 -> 0 | Q27: =+'Sprint1 '!N29 -> 0 | ... AC27: =+'Sprint1 '!Z29 -> 0
A28: Información general | B28: 4.5507692 | C28: Sin Riesgo | D28: =VLOOKUP(C28,$AQ$59:$AR$64,2,0) -> 0 | E28: =+Z28 -> 9 | G28: =VLOOKUP(F28,$AN$59:$AO$70,2,0) -> #N/A | H28: =+D28*B28+B28 -> 4.5507692 | I28: =+H28 -> 4.5507692 | J28: =+'Sprint1 '!G30 -> 5 | K28: =+'Sprint1 '!H30 -> 9 | L28: =+'Sprint1 '!I30 -> 9 | M28: =+'Sprint1 '!J30 -> 9 | N28: =+'Sprint1 '!K30 -> 9 | O28: =+'Sprint1 '!L30 -> 9 | P28: =+'Sprint1 '!M30 -> 9 | Q28: =+'Sprint1 '!N30 -> 9 | ... AC28: =+'Sprint1 '!Z30 -> 9
A29: Visión General | B29: 11.376923 | C29: Sin Riesgo | D29: =VLOOKUP(C29,$AQ$59:$AR$64,2,0) -> 0 | E29: =+Z29 -> 3 | G29: =VLOOKUP(F29,$AN$59:$AO$70,2,0) -> #N/A | H29: =+D29*B29+B29 -> 11.376923 | I29: =+H29 -> 11.376923 | J29: =+'Sprint1 '!G31 -> 11.376923 | K29: =+'Sprint1 '!H31 -> 5 | L29: =+'Sprint1 '!I31 -> 0 | M29: =+'Sprint1 '!J31 -> 0 | N29: =+'Sprint1 '!K31 -> 3 | O29: =+'Sprint1 '!L31 -> 3 | P29: =+'Sprint1 '!M31 -> 3 | Q29: =+'Sprint1 '!N31 -> 3 | ... AC29: =+'Sprint1 '!Z31 -> 3
A30: Caidas | B30: 11.376923 | C30: Sin Riesgo | D30: =VLOOKUP(C30,$AQ$59:$AR$64,2,0) -> 0 | E30: =+Z30 -> 0 | G30: =VLOOKUP(F30,$AN$59:$AO$70,2,0) -> #N/A | H30: =+D30*B30+B30 -> 11.376923 | I30: =+H30 -> 11.376923 | J30: =+'Sprint1 '!G32 -> 11.376923 | K30: =+'Sprint1 '!H32 -> 11 | L30: =+'Sprint1 '!I32 -> 0 | M30: =+'Sprint1 '!J32 -> 0 | N30: =+'Sprint1 '!K32 -> 0 | O30: =+'Sprint1 '!L32 -> 0 | P30: =+'Sprint1 '!M32 -> 0 | Q30: =+'Sprint1 '!N32 -> 0 | ... AC30: =+'Sprint1 '!Z32 -> 0
A31: Incidencas | B31: 5.1196154 | C31: Sin Riesgo | D31: =VLOOKUP(C31,$AQ$59:$AR$64,2,0) -> 0 | E31: =+Z31 -> 0 | G31: =VLOOKUP(F31,$AN$59:$AO$70,2,0) -> #N/A | H31: =+D31*B31+B31 -> 5.1196154 | I31: =+H31 -> 5.1196154 | J31: =+'Sprint1 '!G33 -> 5.1196154 | K31: =+'Sprint1 '!H33 -> 0 | L31: =+'Sprint1 '!I33 -> 0 | M31: =+'Sprint1 '!J33 -> 0 | N31: =+'Sprint1 '!K33 -> 0 | O31: =+'Sprint1 '!L33 -> 0 | P31: =+'Sprint1 '!M33 -> 0 | Q31: =+'Sprint1 '!N33 -> 0 | ... AC31: =+'Sprint1 '!Z33 -> 0
A32: Generales | B32: 1.7065385 | C32: Sin Riesgo | D32: =VLOOKUP(C32,$AQ$59:$AR$64,2,0) -> 0 | E32: =+Z32 -> 0 | G32: =VLOOKUP(F32,$AN$59:$AO$70,2,0) -> #N/A | H32: =+D32*B32+B32 -> 1.7065385 | I32: =+H32 -> 1.7065385 | J32: =+'Sprint1 '!G34 -> 1.7065385 | K32: =+'Sprint1 '!H34 -> 0 | L32: =+'Sprint1 '!I34 -> 0 | M32: =+'Sprint1 '!J34 -> 0 | N32: =+'Sprint1 '!K34 -> 0 | O32: =+'Sprint1 '!L34 -> 0 | P32: =+'Sprint1 '!M34 -> 0 | Q32: =+'Sprint1 '!N34 -> 0 | ... AC32: =+'Sprint1 '!Z34 -> 0
A33: Tareas | B33: 1.7065385 | C33: Sin Riesgo | D33: =VLOOKUP(C33,$AQ$59:$AR$64,2,0) -> 0 | E33: =+Z33 -> 0 | G33: =VLOOKUP(F33,$AN$59:$AO$70,2,0) -> #N/A | H33: =+D33*B33+B33 -> 1.7065385 | I33: =+H33 -> 1.7065385 | J33: =+'Sprint1 '!G35 -> 1.7065385 | K33: =+'Sprint1 '!H35 -> 0 | L33: =+'Sprint1 '!I35 -> 0 | M33: =+'Sprint1 '!J35 -> 0 | N33: =+'Sprint1 '!K35 -> 0 | O33: =+'Sprint1 '!L35 -> 0 | P33: =+'Sprint1 '!M35 -> 0 | Q33: =+'Sprint1 '!N35 -> 0 | ... AC33: =+'Sprint1 '!Z35 -> 0
A34: Alertas Medicación | B34: 1.7065385 | C34: Sin Riesgo | D34: =VLOOKUP(C34,$AQ$59:$AR$64,2,0) -> 0 | E34: =+Z34 -> 0 | G34: =VLOOKUP(F34,$AN$59:$AO$70,2,0) -> #N/A | H34: =+D34*B34+B34 -> 1.7065385 | I34: =+H34 -> 1.7065385 | J34: =+'Sprint1 '!G36 -> 1.7065385 | K34: =+'Sprint1 '!H36 -> 0 | L34: =+'Sprint1 '!I36 -> 0 | M34: =+'Sprint1 '!J36 -> 0 | N34: =+'Sprint1 '!K36 -> 0 | O34: =+'Sprint1 '!L36 -> 0 | P34: =+'Sprint1 '!M36 -> 0 | Q34: =+'Sprint1 '!N36 -> 0 | ... AC34: =+'Sprint1 '!Z36 -> 0
A35: Visitas | B35: 11.376923 | C35: Sin Riesgo | D35: =VLOOKUP(C35,$AQ$59:$AR$64,2,0) -> 0 | E35: =+Z35 -> 0 | G35: =VLOOKUP(F35,$AN$59:$AO$70,2,0) -> #N/A | H35: =+D35*B35+B35 -> 11.376923 | I35: =+H35 -> 11.376923 | J35: =+'Sprint1 '!G37 -> 11.376923 | K35: =+'Sprint1 '!H37 -> 11 | L35: =+'Sprint1 '!I37 -> 0 | M35: =+'Sprint1 '!J37 -> 0 | N35: =+'Sprint1 '!K37 -> 0 | O35: =+'Sprint1 '!L37 -> 0 | P35: =+'Sprint1 '!M37 -> 0 | Q35: =+'Sprint1 '!N37 -> 0 | ... AC35: =+'Sprint1 '!Z37 -> 0
A36: Médico | B36: 4.5507692 | C36: Sin Riesgo | D36: =VLOOKUP(C36,$AQ$59:$AR$64,2,0) -> 0 | E36: =+Z36 -> 0 | G36: =VLOOKUP(F36,$AN$59:$AO$70,2,0) -> #N/A | H36: =+D36*B36+B36 -> 4.5507692 | I36: =+H36 -> 4.5507692 | J36: =+'Sprint1 '!G38 -> 4.5507692 | K36: =+'Sprint1 '!H38 -> 4.5507692 | L36: =+'Sprint1 '!I38 -> 4.5507692 | M36: =+'Sprint1 '!J38 -> 10 | N36: =+'Sprint1 '!K38 -> 0 | O36: =+'Sprint1 '!L38 -> 0 | P36: =+'Sprint1 '!M38 -> 0 | Q36: =+'Sprint1 '!N38 -> 0 | ... AC36: =+'Sprint1 '!Z38 -> 0
... A52: Correcciones y DOC entrega | B52: 20 | C52: Medio | D52: =VLOOKUP(C52,$AQ$59:$AR$64,2,0) -> 0.4 | E52: =+Z52 -> 11 | G52: =VLOOKUP(F52,$AN$59:$AO$70,2,0) -> #N/A | H52: =+D52*B52+B52 -> 28 | I52: =+H52 -> 28 | J52: =+'Sprint1 '!G54 -> 28 | K52: =+'Sprint1 '!H54 -> 28 | L52: =+'Sprint1 '!I54 -> 28 | M52: =+'Sprint1 '!J54 -> 28 | N52: =+'Sprint1 '!K54 -> 28 | O52: =+'Sprint1 '!L54 -> 11 | P52: =+'Sprint1 '!M54 -> 11 | Q52: =+'Sprint1 '!N54 -> 11 | ... AC52: =+'Sprint1 '!Z54 -> 11
C53: Sin Riesgo | D53: =VLOOKUP(C53,$AQ$59:$AR$64,2,0) -> 0 | E53: =+Z53 -> 0 | G53: =VLOOKUP(F53,$AN$59:$AO$70,2,0) -> #N/A | H53: =+D53*B53+B53 -> 0 | I53: =+H53 -> 0 | J53: =+'Sprint1 '!G55 -> 0 | K53: =+'Sprint1 '!H55 -> 0 | L53: =+'Sprint1 '!I55 -> 0 | M53: =+'Sprint1 '!J55 -> 0 | N53: =+'Sprint1 '!K55 -> 0 | O53: =+'Sprint1 '!L55 -> 0 | P53: =+'Sprint1 '!M55 -> 0 | Q53: =+'Sprint1 '!N55 -> 0 | ... AC53: =+'Sprint1 '!Z55 -> 0
A54: Buffer CCPM 50 hs | C54: Sin Riesgo | D54: =VLOOKUP(C54,$AQ$59:$AR$64,2,0) -> 0 | E54: =+Z54 -> 0 | G54: =VLOOKUP(F54,$AN$59:$AO$70,2,0) -> #N/A | H54: =+D54*B54+B54 -> 0 | I54: =+H54 -> 0 | J54: =+'Sprint1 '!G56 -> 0 | K54: =+'Sprint1 '!H56 -> 0 | L54: =+'Sprint1 '!I56 -> 0 | M54: =+'Sprint1 '!J56 -> 0 | N54: =+'Sprint1 '!K56 -> 0 | O54: =+'Sprint1 '!L56 -> 0 | P54: =+'Sprint1 '!M56 -> 0 | Q54: =+'Sprint1 '!N56 -> 0 | ... AC54: =+'Sprint1 '!Z56 -> 0
A55: Administracion Proyecto | B55: 50 | C55: Sin Riesgo | D55: =VLOOKUP(C55,$AQ$59:$AR$64,2,0) -> 0 | E55: =+Z55 -> 20 | G55: =VLOOKUP(F55,$AN$59:$AO$70,2,0) -> #N/A | H55: =+D55*B55+B55 -> 50 | I55: =+H55 -> 50 | J55: =+'Sprint1 '!G57 -> 50 | K55: =+'Sprint1 '!H57 -> 50 | L55: =+'Sprint1 '!I57 -> 50 | M55: =+'Sprint1 '!J57 -> 50 | N55: =+'Sprint1 '!K57 -> 50 | O55: =+'Sprint1 '!L57 -> 20 | P55: =+'Sprint1 '!M57 -> 20 | Q55: =+'Sprint1 '!N57 -> 20 | ... AC55: =+'Sprint1 '!Z57 -> 20
AN58: Valor Tarea: Otorgado por el Cliente | AQ58: Riesgo
AN59: No Relevante | AO59: 100 | AQ59: Sin Riesgo | AR59: 0
...

Sheet Sprint1 
E2: CÓDIGO
C3: Plan de Iteración | E3: F-PE-CYMP-007-005
E4: VERSIÓN: 1.0.0 Beta
A6: Área de Proyectos
A7: Elaboró: asf | C7: Aprobó: | E7: Revisó:
A8: METODOS AGILES SCRUM
B9: DIA | C9: =+'Resumen Sprints'!I9 -> 40072.48
A10: SPRINT 2 BACKLOG
A11: Cargar el dia 1 en "T Ideal" el Total acumulado y poner zero al dia estimado de fin del sprit
A12: Cargar las Referencias a las tareas , Asignar recursos , definir estados y cargar esfuerzo restante a partir del dia 2 marcar con rojo las cargas manuales
A13: Actualizar al dia de hoy la referencia de la fila "T Restante Real" copiando la formula del dia 1
F14: 0 | G14: 0 | H14: 0 | I14: 0 | J14: 0 | K14: 0 | L14: 0 | M14: 0 | N14: 0 | O14: 0 | P14: 0 | Q14: 0 | R14: 0 | S14: 0 | T14: 0 | U14: 0 | V14: 0 | W14: 0 | X14: 0 | Y14: 0 | Z14: 0
A15: Titulo Importante | B15: Recursos | C15: Esfuerzo Diario | D15: Esfuerzo Restante | E15: Estado | F15: Trabajo Pendiente | O15: reprogramacion de fechas y tareas | Y15: LIMITES
E16: D. Lab. | F16: =+'Resumen Sprints'!I14 -> 1 | G16: =+'Resumen Sprints'!J14 -> 2 | H16: =+'Resumen Sprints'!K14 -> 3 | I16: =+'Resumen Sprints'!L14 -> 4 | J16: =+'Resumen Sprints'!M14 -> 5 | K16: =+'Resumen Sprints'!N14 -> 6 | L16: =+'Resumen Sprints'!O14 -> 7 | M16: =+'Resumen Sprints'!P14 -> 8 | ... Z16: =+'Resumen Sprints'!AC14 -> 21
E17: Fecha | F17: 39919 | G17: 39920 | H17: 39921 | I17: 39922 | J17: 39923 | K17: 39924 | L17: 39925 | M17: 39926 | N17: 39927 | O17: 39928 | P17: 39929 | Q17: 39930 | R17: 39931 | S17: 39932 | T17: 39933 | U17: 39934 | V17: 39935 | W17: 39936 | X17: 39937 | Y17: 39938 | Z17: 39939
A18: 3 | E18: hoy | F18: =IF(F19>0,$F$19,0) -> 323.43269 | G18: =IF(G19>0,$F$19,0) -> 323.43269 | H18: =IF(H19>0,$F$19,0) -> 323.43269 | I18: =IF(I19>0,$F$19,0) -> 323.43269 | J18: =IF(J19>0,$F$19,0) -> 323.43269 | K18: =IF(K19>0,$F$19,0) -> 323.43269 | L18: =IF(L19>0,$F$19,0) -> 323.43269 | M18: =IF(M19>0,$F$19,0) -> 323.43269 | ... Z18: =IF(Z19>0,$F$19,0) -> 0
E19: T Restante Real | F19: =IF(F17<=TODAY(),F26,"") -> 323.43269 | G19: =IF(G17<=TODAY(),G26,"") -> 318.88192 | H19: =IF(H17<=TODAY(),H26,"") -> 300.10577 | I19: =IF(I17<=TODAY(),I26,"") -> 273.10577 | J19: =IF(J17<=TODAY(),J26,"") -> 278.555 | K19: =IF(K17<=TODAY(),K26,"") -> 248.80115 | L19: =IF(L17<=TODAY(),L26,"") -> 100.55077 | M19: =IF(M17<=TODAY(),M26,"") -> 100.55077 | N19: =IF(N17<=TODAY(),N26,"") -> 100.55077
E20: Buffer Critico | F20: =$D$22*Sheet2!$G$69/1000*1.3 -> 1.6430556 | G20: =IF(F20+G23>$F$20,$F$20,F20+G23) -> 1.1261444 | H20: =IF(G20+H23>$F$20,$F$20,G20+H23) -> 0.45190833 | I20: =IF(H20+I23>$F$20,$F$20,H20+I23) -> -0.17177222 | J20: =IF(I20+J23>$F$20,$F$20,I20+J23) -> -1.5651417 | K20: =IF(J20+K23>$F$20,$F$20,J20+K23) -> -2.8383444 | L20: =IF(K20+L23>$F$20,$F$20,K20+L23) -> -0.99605139 | M20: =IF(L20+M23>$F$20,$F$20,L20+M23) -> 0.21429722 | N20: =IF(M20+N23>$F$20,$F$20,M20+N23) -> 0.79270139
C21: 1 | E21: presuEstim | F21: =+F26*Sheet2!$G$69/1000*1 -> 8.1756597 | G21: =+F21-$C$25/1000 -> 7.5437153 | H21: =+G21-$C$25/1000 -> 6.9117708 | I21: =+H21-$C$25/1000 -> 6.2798264 | J21: =+I21-$C$25/1000 -> 5.6478819 | K21: =+J21-$C$25/1000 -> 5.0159375 | L21: =+K21-$C$25/1000 -> 4.3839931 | M21: =+L21-$C$25/1000 -> 3.7520486 | N21: =+M21-$C$25/1000 -> 3.1201042 | ... Z21: =+Y21-$C$25/1000 -> -4.4632292
D22: 50 | E22: BUFFER | F22: =$D$22*Sheet2!$G$69/1000 -> 1.2638889 | G22: =IF(F22+G23>$F$22,$F$22,F22+G23) -> 0.74697778 | H22: =IF(G22+H23>$F$22,$F$22,G22+H23) -> 0.072741667 | I22: =IF(H22+I23>$F$22,$F$22,H22+I23) -> -0.55093889 | J22: =IF(I22+J23>$F$22,$F$22,I22+J23) -> -1.9443083 | K22: =IF(J22+K23>$F$22,$F$22,J22+K23) -> -3.2175111 | L22: =IF(K22+L23>$F$22,$F$22,K22+L23) -> -1.3752181 | M22: =IF(L22+M23>$F$22,$F$22,L22+M23) -> -0.16486944 | N22: =IF(M22+N23>$F$22,$F$22,M22+N23) -> 0.41353472
E23: desvio$ | F23: =+F21-F24 -> 0 | G23: =+G21-G24 -> -0.51691111 | H23: =+H21-H24 -> -0.67423611 | I23: =+I21-I24 -> -0.62368056 | J23: =+J21-J24 -> -1.3933694 | K23: =+K21-K24 -> -1.2732028 | L23: =+L21-L24 -> 1.8422931 | M23: =+M21-M24 -> 1.2103486 | N23: =+N21-N24 -> 0.57840417
E24: Agastar$ | F24: =+F26*Sheet2!$G$69/1000* $C$21 -> 8.1756597 | G24: =+G26*Sheet2!$G$69/1000* $C$21 -> 8.0606264 | H24: =+H26*Sheet2!$G$69/1000* $C$21 -> 7.5860069 | I24: =+I26*Sheet2!$G$69/1000* $C$21 -> 6.9035069 | J24: =+J26*Sheet2!$G$69/1000* $C$21 -> 7.0412514 | K24: =+K26*Sheet2!$G$69/1000* $C$21 -> 6.2891403 | L24: =+L26*Sheet2!$G$69/1000* $C$21 -> 2.5417 | M24: =+M26*Sheet2!$G$69/1000* $C$21 -> 2.5417 | N24: =+N26*Sheet2!$G$69/1000* $C$21 -> 2.5417
C25: =+C26*Sheet2!$G$69 -> 631.94444 | E25: T ideal | F25: =+F26 -> 323.43269 | R25: 0
C26: =+AM81 -> 25 | D26: =SUM(D27:D62) -> 100.55077 | E26: T. Acum | F26: =SUM(F27:F62) -> 323.43269 | G26: =SUM(G27:G62) -> 318.88192 | H26: =SUM(H27:H62) -> 300.10577 | I26: =SUM(I27:I62) -> 273.10577 | J26: =SUM(J27:J62) -> 278.555 | K26: =SUM(K27:K62) -> 248.80115 | L26: =SUM(L27:L62) -> 100.55077 | M26: =SUM(M27:M62) -> 100.55077 | ... Z26: =SUM(Z27:Z62) -> 100.55077
A27: =+'Resumen Sprints'!A25 -> Expediente Personal Clínico Social | B27: EAN | C27: =VLOOKUP(B27,$AL$69:$AM$86,2,0) -> 8 | D27: =+Z27 -> 0 | E27: Pendiente | F27: =+'Resumen Sprints'!I25 -> 4.5507692 | G27: 0 | H27: =+G27 -> 0 | I27: =+H27 -> 0 | J27: =+I27 -> 0 | K27: =+J27 -> 0 | L27: =+K27 -> 0 | M27: =+L27 -> 0 | N27: =+M27 -> 0 | O27: =+N27 -> 0 | ... Z27: =+Y27 -> 0
A28: =+'Resumen Sprints'!A26 -> Arbol de centros | B28: EAN | C28: =VLOOKUP(B28,$AL$69:$AM$86,2,0) -> 8 | D28: =+Z28 -> 11 | E28: Pendiente | F28: =+'Resumen Sprints'!I26 -> 11.376923 | G28: =+F28 -> 11.376923 | H28: 11 | I28: =+H28 -> 11 | J28: =+I28 -> 11 | K28: =+J28 -> 11 | L28: =+K28 -> 11 | M28: =+L28 -> 11 | N28: =+M28 -> 11 | O28: =+N28 -> 11 | P28: =+O28 -> 11 | ... Z28: =+Y28 -> 11
A29: =+'Resumen Sprints'!A27 -> Listado de residentes | B29: EAN | C29: =VLOOKUP(B29,$AL$69:$AM$86,2,0) -> 8 | D29: =+Z29 -> 0 | E29: Pendiente | F29: =+'Resumen Sprints'!I27 -> 4.5507692 | G29: =+F29 -> 4.5507692 | H29: 0 | I29: 0 | J29: =+I29 -> 0 | K29: =+J29 -> 0 | L29: =+K29 -> 0 | M29: =+L29 -> 0 | N29: =+M29 -> 0 | O29: =+N29 -> 0 | P29: =+O29 -> 0 | Q29: =+P29 -> 0 | ... Z29: =+Y29 -> 0
A30: =+'Resumen Sprints'!A28 -> Información general | B30: EAN | C30: =VLOOKUP(B30,$AL$69:$AM$86,2,0) -> 8 | D30: =+Z30 -> 9 | E30: Pendiente | F30: 5 | G30: =+F30 -> 5 | H30: 9 | I30: 9 | J30: =+I30 -> 9 | K30: =+J30 -> 9 | L30: =+K30 -> 9 | M30: =+L30 -> 9 | N30: =+M30 -> 9 | O30: =+N30 -> 9 | P30: =+O30 -> 9 | Q30: =+P30 -> 9 | ... Z30: =+Y30 -> 9
A31: =+'Resumen Sprints'!A29 -> Visión General | B31: EAN | C31: =VLOOKUP(B31,$AL$69:$AM$86,2,0) -> 8 | D31: =+Z31 -> 3 | E31: Pendiente | F31: =+'Resumen Sprints'!I29 -> 11.376923 | G31: =+F31 -> 11.376923 | H31: 5 | I31: 0 | J31: =+I31 -> 0 | K31: 3 | L31: =+K31 -> 3 | M31: =+L31 -> 3 | N31: =+M31 -> 3 | O31: =+N31 -> 3 | P31: =+O31 -> 3 | Q31: =+P31 -> 3 | R31: =+Q31 -> 3 | S31: =+R31 -> 3 | ... Z31: =+Y31 -> 3
A32: =+'Resumen Sprints'!A30 -> Caidas | B32: EAN | C32: =VLOOKUP(B32,$AL$69:$AM$86,2,0) -> 8 | D32: =+Z32 -> 0 | E32: Pendiente | F32: =+'Resumen Sprints'!I30 -> 11.376923 | G32: =+F32 -> 11.376923 | H32: 11 | I32: 0 | J32: =+I32 -> 0 | K32: =+J32 -> 0 | L32: =+K32 -> 0 | M32: =+L32 -> 0 | N32: =+M32 -> 0 | O32: =+N32 -> 0 | P32: =+O32 -> 0 | Q32: =+P32 -> 0 | ... Z32: =+Y32 -> 0
A33: =+'Resumen Sprints'!A31 -> Incidencas | B33: EAN | C33: =VLOOKUP(B33,$AL$69:$AM$86,2,0) -> 8 | D33: =+Z33 -> 0 | E33: Pendiente | F33: =+'Resumen Sprints'!I31 -> 5.1196154 | G33: =+F33 -> 5.1196154 | H33: 0 | I33: 0 | J33: =+I33 -> 0 | K33: =+J33 -> 0 | L33: =+K33 -> 0 | M33: =+L33 -> 0 | N33: =+M33 -> 0 | O33: =+N33 -> 0 | P33: =+O33 -> 0 | Q33: =+P33 -> 0 | ... Z33: =+Y33 -> 0
A34: =+'Resumen Sprints'!A32 -> Generales | B34: EAN | C34: =VLOOKUP(B34,$AL$69:$AM$86,2,0) -> 8 | D34: =+Z34 -> 0 | E34: Pendiente | F34: =+'Resumen Sprints'!I32 -> 1.7065385 | G34: =+F34 -> 1.7065385 | H34: 0 | I34: 0 | J34: =+I34 -> 0 | K34: =+J34 -> 0 | L34: =+K34 -> 0 | M34: =+L34 -> 0 | N34: =+M34 -> 0 | O34: =+N34 -> 0 | P34: =+O34 -> 0 | Q34: =+P34 -> 0 | ... Z34: =+Y34 -> 0
A35: =+'Resumen Sprints'!A33 -> Tareas | B35: EAN | C35: =VLOOKUP(B35,$AL$69:$AM$86,2,0) -> 8 | D35: =+Z35 -> 0 | E35: Pendiente | F35: =+'Resumen Sprints'!I33 -> 1.7065385 | G35: =+F35 -> 1.7065385 | H35: 0 | I35: 0 | J35: =+I35 -> 0 | K35: =+J35 -> 0 | L35: =+K35 -> 0 | M35: =+L35 -> 0 | N35: =+M35 -> 0 | O35: =+N35 -> 0 | P35: =+O35 -> 0 | Q35: =+P35 -> 0 | ... Z35: =+Y35 -> 0
A36: =+'Resumen Sprints'!A34 -> Alertas Medicación | B36: EAN | C36: =VLOOKUP(B36,$AL$69:$AM$86,2,0) -> 8 | D36: =+Z36 -> 0 | E36: Pendiente | F36: =+'Resumen Sprints'!I34 -> 1.7065385 | G36: =+F36 -> 1.7065385 | H36: 0 | I36: 0 | J36: =+I36 -> 0 | K36: =+J36 -> 0 | L36: =+K36 -> 0 | M36: =+L36 -> 0 | N36: =+M36 -> 0 | O36: =+N36 -> 0 | P36: =+O36 -> 0 | Q36: =+P36 -> 0 | ... Z36: =+Y36 -> 0
A37: =+'Resumen Sprints'!A35 -> Visitas | B37: EAN | C37: =VLOOKUP(B37,$AL$69:$AM$86,2,0) -> 8 | D37: =+Z37 -> 0 | E37: Pendiente | F37: =+'Resumen Sprints'!I35 -> 11.376923 | G37: =+F37 -> 11.376923 | H37: 11 | I37: 0 | J37: =+I37 -> 0 | K37: =+J37 -> 0 | L37: =+K37 -> 0 | M37: =+L37 -> 0 | N37: =+M37 -> 0 | O37: =+N37 -> 0 | P37: =+O37 -> 0 | Q37: =+P37 -> 0 | ... Z37: =+Y37 -> 0
A38: =+'Resumen Sprints'!A36 -> Médico | B38: NMA | C38: =VLOOKUP(B38,$AL$69:$AM$86,2,0) -> 8 | D38: =+Z38 -> 0 | E38: Pendiente | F38: =+'Resumen Sprints'!I36 -> 4.5507692 | G38: =+F38 -> 4.5507692 | H38: =+G38 -> 4.5507692 | I38: =+H38 -> 4.5507692 | J38: 10 | K38: 0 | L38: =+K38 -> 0 | M38: =+L38 -> 0 | N38: =+M38 -> 0 | O38: =+N38 -> 0 | P38: =+O38 -> 0 | Q38: =+P38 -> 0 | R38: =+Q38 -> 0 | S38: =+R38 -> 0 | ... Z38: =+Y38 -> 0
A39: =+'Resumen Sprints'!A37 -> Anámnesis | B39: NMA | C39: =VLOOKUP(B39,$AL$69:$AM$86,2,0) -> 8 | D39: =+Z39 -> 0 | E39: Pendiente | F39: =+'Resumen Sprints'!I37 -> 11.376923 | G39: =+F39 -> 11.376923 | H39: =+G39 -> 11.376923 | I39: =+H39 -> 11.376923 | J39: =+I39 -> 11.376923 | K39: 0 | L39: =+K39 -> 0 | M39: =+L39 -> 0 | N39: =+M39 -> 0 | O39: =+N39 -> 0 | P39: =+O39 -> 0 | Q39: =+P39 -> 0 | R39: =+Q39 -> 0 | S39: =+R39 -> 0 | ... Z39: =+Y39 -> 0
A40: =+'Resumen Sprints'!A38 -> Pantalla Incidencias | B40: NMA | C40: =VLOOKUP(B40,$AL$69:$AM$86,2,0) -> 8 | D40: =+Z40 -> 10 | E40: Pendiente | F40: =+'Resumen Sprints'!I38 -> 20.478462 | G40: =+F40 -> 20.478462 | H40: 20 | I40: =+H40 -> 20 | J40: =+I40 -> 20 | K40: 5 | L40: 10 | M40: =+L40 -> 10 | N40: =+M40 -> 10 | O40: =+N40 -> 10 | P40: =+O40 -> 10 | Q40: =+P40 -> 10 | R40: =+Q40 -> 10 | S40: =+R40 -> 10 | T40: =+S40 -> 10 | ... Z40: =+Y40 -> 10
A41: =+'Resumen Sprints'!A39 -> Generales | B41: NMA | C41: =VLOOKUP(B41,$AL$69:$AM$86,2,0) -> 8 | D41: =+Z41 -> 4.5507692 | E41: Pendiente | F41: =+'Resumen Sprints'!I39 -> 4.5507692 | G41: =+F41 -> 4.5507692 | H41: =+G41 -> 4.5507692 | I41: =+H41 -> 4.5507692 | J41: =+I41 -> 4.5507692 | K41: =+J41 -> 4.5507692 | L41: =+K41 -> 4.5507692 | M41: =+L41 -> 4.5507692 | N41: =+M41 -> 4.5507692 | ... Z41: =+Y41 -> 4.5507692
A42: =+'Resumen Sprints'!A40 -> Tareas | B42: NMA | C42: =VLOOKUP(B42,$AL$69:$AM$86,2,0) -> 8 | D42: =+Z42 -> 0 | E42: Pendiente | F42: =+'Resumen Sprints'!I40 -> 4.5507692 | G42: =+F42 -> 4.5507692 | H42: =+G42 -> 4.5507692 | I42: =+H42 -> 4.5507692 | J42: =+I42 -> 4.5507692 | K42: =+J42 -> 4.5507692 | L42: 0 | M42: =+L42 -> 0 | N42: =+M42 -> 0 | O42: =+N42 -> 0 | P42: =+O42 -> 0 | Q42: =+P42 -> 0 | R42: =+Q42 -> 0 | S42: =+R42 -> 0 | T42: =+S42 -> 0 | ... Z42: =+Y42 -> 0
...

Sheet Sheet2
A4: COSTOS
D21: =+'Sprint1 '!D26 -> 100.55077 | E21: =+'Sprint1 '!E26 -> T. Acum | F21: =+'Sprint1 '!F26 -> 323.43269 | G21: Costohs | H21: costoSub | I21: GastoHs | J21: Gasto$
A22: =+'Sprint1 '!A27 -> Expediente Personal Clínico Social | B22: =+'Sprint1 '!B27 -> EAN | C22: =+'Sprint1 '!C27 -> 8 | D22: =+'Sprint1 '!D27 -> 0 | E22: =+'Sprint1 '!E27 -> Pendiente | F22: =+'Sprint1 '!F27 -> 4.5507692 | G22: =VLOOKUP(B22,'Sprint1 '!$AL$69:$AN$86,3,0) -> 20 | H22: =+G22*F22 -> 91.015385 | I22: =IF(F22-D22>0,F22-D22,F22) -> 4.5507692 | J22: =+I22*G22 -> 91.015385
A23: =+'Sprint1 '!A28 -> Arbol de centros | B23: =+'Sprint1 '!B28 -> EAN | C23: =+'Sprint1 '!C28 -> 8 | D23: =+'Sprint1 '!D28 -> 11 | E23: =+'Sprint1 '!E28 -> Pendiente | F23: =+'Sprint1 '!F28 -> 11.376923 | G23: =VLOOKUP(B23,'Sprint1 '!$AL$69:$AN$86,3,0) -> 20 | H23: =+G23*F23 -> 227.53846 | I23: =IF(F23-D23>0,F23-D23,F23) -> 0.37692308 | J23: =+I23*G23 -> 7.5384615
A24: =+'Sprint1 '!A29 -> Listado de residentes | B24: =+'Sprint1 '!B29 -> EAN | C24: =+'Sprint1 '!C29 -> 8 | D24: =+'Sprint1 '!D29 -> 0 | E24: =+'Sprint1 '!E29 -> Pendiente | F24: =+'Sprint1 '!F29 -> 4.5507692 | G24: =VLOOKUP(B24,'Sprint1 '!$AL$69:$AN$86,3,0) -> 20 | H24: =+G24*F24 -> 91.015385 | I24: =IF(F24-D24>0,F24-D24,F24) -> 4.5507692 | J24: =+I24*G24 -> 91.015385
A25: =+'Sprint1 '!A30 -> Información general | B25: =+'Sprint1 '!B30 -> EAN | C25: =+'Sprint1 '!C30 -> 8 | D25: =+'Sprint1 '!D30 -> 9 | E25: =+'Sprint1 '!E30 -> Pendiente | F25: =+'Sprint1 '!F30 -> 5 | G25: =VLOOKUP(B25,'Sprint1 '!$AL$69:$AN$86,3,0) -> 20 | H25: =+G25*F25 -> 100 | I25: =IF(F25-D25>0,F25-D25,F25) -> 5 | J25: =+I25*G25 -> 100
A26: =+'Sprint1 '!A31 -> Visión General | B26: =+'Sprint1 '!B31 -> EAN | C26: =+'Sprint1 '!C31 -> 8 | D26: =+'Sprint1 '!D31 -> 3 | E26: =+'Sprint1 '!E31 -> Pendiente | F26: =+'Sprint1 '!F31 -> 11.376923 | G26: =VLOOKUP(B26,'Sprint1 '!$AL$69:$AN$86,3,0) -> 20 | H26: =+G26*F26 -> 227.53846 | I26: =IF(F26-D26>0,F26-D26,F26) -> 8.3769231 | J26: =+I26*G26 -> 167.53846
A27: =+'Sprint1 '!A32 -> Caidas | B27: =+'Sprint1 '!B32 -> EAN | C27: =+'Sprint1 '!C32 -> 8 | D27: =+'Sprint1 '!D32 -> 0 | E27: =+'Sprint1 '!E32 -> Pendiente | F27: =+'Sprint1 '!F32 -> 11.376923 | G27: =VLOOKUP(B27,'Sprint1 '!$AL$69:$AN$86,3,0) -> 20 | H27: =+G27*F27 -> 227.53846 | I27: =IF(F27-D27>0,F27-D27,F27) -> 11.376923 | J27: =+I27*G27 -> 227.53846
A28: =+'Sprint1 '!A33 -> Incidencas | B28: =+'Sprint1 '!B33 -> EAN | C28: =+'Sprint1 '!C33 -> 8 | D28: =+'Sprint1 '!D33 -> 0 | E28: =+'Sprint1 '!E33 -> Pendiente | F28: =+'Sprint1 '!F33 -> 5.1196154 | G28: =VLOOKUP(B28,'Sprint1 '!$AL$69:$AN$86,3,0) -> 20 | H28: =+G28*F28 -> 102.39231 | I28: =IF(F28-D28>0,F28-D28,F28) -> 5.1196154 | J28: =+I28*G28 -> 102.39231
A29: =+'Sprint1 '!A34 -> Generales | B29: =+'Sprint1 '!B34 -> EAN | C29: =+'Sprint1 '!C34 -> 8 | D29: =+'Sprint1 '!D34 -> 0 | E29: =+'Sprint1 '!E34 -> Pendiente | F29: =+'Sprint1 '!F34 -> 1.7065385 | G29: =VLOOKUP(B29,'Sprint1 '!$AL$69:$AN$86,3,0) -> 20 | H29: =+G29*F29 -> 34.130769 | I29: =IF(F29-D29>0,F29-D29,F29) -> 1.7065385 | J29: =+I29*G29 -> 34.130769
A30: =+'Sprint1 '!A35 -> Tareas | B30: =+'Sprint1 '!B35 -> EAN | C30: =+'Sprint1 '!C35 -> 8 | D30: =+'Sprint1 '!D35 -> 0 | E30: =+'Sprint1 '!E35 -> Pendiente | F30: =+'Sprint1 '!F35 -> 1.7065385 | G30: =VLOOKUP(B30,'Sprint1 '!$AL$69:$AN$86,3,0) -> 20 | H30: =+G30*F30 -> 34.130769 | I30: =IF(F30-D30>0,F30-D30,F30) -> 1.7065385 | J30: =+I30*G30 -> 34.130769
A31: =+'Sprint1 '!A36 -> Alertas Medicación | B31: =+'Sprint1 '!B36 -> EAN | C31: =+'Sprint1 '!C36 -> 8 | D31: =+'Sprint1 '!D36 -> 0 | E31: =+'Sprint1 '!E36 -> Pendiente | F31: =+'Sprint1 '!F36 -> 1.7065385 | G31: =VLOOKUP(B31,'Sprint1 '!$AL$69:$AN$86,3,0) -> 20 | H31: =+G31*F31 -> 34.130769 | I31: =IF(F31-D31>0,F31-D31,F31) -> 1.7065385 | J31: =+I31*G31 -> 34.130769
A32: =+'Sprint1 '!A37 -> Visitas | B32: =+'Sprint1 '!B37 -> EAN | C32: =+'Sprint1 '!C37 -> 8 | D32: =+'Sprint1 '!D37 -> 0 | E32: =+'Sprint1 '!E37 -> Pendiente | F32: =+'Sprint1 '!F37 -> 11.376923 | G32: =VLOOKUP(B32,'Sprint1 '!$AL$69:$AN$86,3,0) -> 20 | H32: =+G32*F32 -> 227.53846 | I32: =IF(F32-D32>0,F32-D32,F32) -> 11.376923 | J32: =+I32*G32 -> 227.53846
A33: =+'Sprint1 '!A38 -> Médico | B33: =+'Sprint1 '!B38 -> NMA | C33: =+'Sprint1 '!C38 -> 8 | D33: =+'Sprint1 '!D38 -> 0 | E33: =+'Sprint1 '!E38 -> Pendiente | F33: =+'Sprint1 '!F38 -> 4.5507692 | G33: =VLOOKUP(B33,'Sprint1 '!$AL$69:$AN$86,3,0) -> 20 | H33: =+G33*F33 -> 91.015385 | I33: =IF(F33-D33>0,F33-D33,F33) -> 4.5507692 | J33: =+I33*G33 -> 91.015385
... A57: =+'Sprint1 '!A62 | B57: =+'Sprint1 '!B62 -> Sin Asignar | C57: =+'Sprint1 '!C62 -> 0 | D57: =+'Sprint1 '!D62 -> 0 | E57: =+'Sprint1 '!E62 -> Pendiente | F57: =+'Sprint1 '!F62 -> 0 | G57: =VLOOKUP(B57,'Sprint1 '!$AL$69:$AN$86,3,0) -> 40 | H57: =+G57*F57 -> 0 | I57: =IF(F57-D57>0,F57-D57,F57) -> 0 | J57: =+I57*G57 -> 0
A69: TOTALES | F69: =SUM(F22:F68) -> 323.43269 | G69: =AVERAGE(G22:G68) -> 25.277778 | H69: =SUM(H22:H68) -> 8788.6538 | I69: =SUM(I22:I68) -> 247.43269 | J69: =SUM(J22:J68) -> 6553.6538

Sheet Resumen
F2: CÓDIGO
D3: Plan de Iteración | F3: F-PE-CYMP-007-005
F4: VERSIÓN: 1.0.0
B6: Área de Proyectos
B7: Elaboró: | D7: Aprobó: | F7: Revisó:
B11: METODOS AGILES SCRUM
G12: -1.29 | K12: 39665.891
C13: Nombre | D13: Proyecto A
C14: Fecha de Inicio | D14: =+'Resumen Sprints'!I15 -> 39861
C15: Fecha Fin | D15: =+D14+63 -> 39924
F18: PANEL DE CONTROL
C20: Esfuerzo Estimado | D20: Esfuerzo Utilizado | E20: Esfuerzo Restante | F20: Indice Veloc. | G20: Velocidad | H20: Vel Normal | I20: Fecha de Inicio | J20: Fecha Fin | K20: Fin Estimado
B21: Inicio Scrum | C21: =+'Resumen Sprints'!H18 -> 5 | D21: =+C21-E21 -> 0 | E21: =+'Resumen Sprints'!E18 -> 5 | I21: =+'Resumen Sprints'!I15 -> 39861 | J21: =+'Resumen Sprints'!J15 -> 39862 | K21: 38693
B22: Spring 1 | C22: =+'Resumen Sprints'!H24 -> 322.98346 | D22: =+C22-E22 -> 222.43269 | E22: =+'Resumen Sprints'!E24 -> 100.55077 | F22: =+G22/H22*-1 -> -1.2131813 | G22: -9.1125 | H22: =+C22/(J22-I22) -> -7.5112433 | I22: =+'Sprint1 '!F17 -> 39919 | J22: =+'Resumen Sprints'!U15 -> 39876 | K22: =+'Resumen Sprints'!V15 -> 39877
B23: Spring 2 | C23: 0 | D23: =+C23-E23 -> -10 | E23: =+'Resumen Sprints'!E38 -> 10 | F23: =+G23/H23*-1 -> #DIV/0! | G23: 4.4 | H23: =+C23/(J23-I23) -> 0 | I23: =+'Resumen Sprints'!V15 -> 39877 | J23: =+I23+20 -> 39897
B24: Spring Futuros | C24: =+'Resumen Sprints'!H47 -> 10 | D24: =+C24-E24 -> 10 | E24: =+'Resumen Sprints'!E47 -> 0 | F24: =+G24/H24*-1 -> -11.88 | G24: 4.4 | H24: =+C24/(J24-I24) -> 0.37037037 | I24: =+J23 -> 39897 | J24: =+D15 -> 39924
B25: Totales | C25: =SUM(C21:C24) -> 337.98346 | D25: =SUM(D21:D24) -> 222.43269 | E25: =SUM(E21:E24) -> 115.55077 | G25: =AVERAGE(G21:G24) -> -0.10416667 | I25: =+I21 -> 39861 | J25: =+J24 -> 39924
B26: Tot. En Dias | C26: =+C25/$E$36 -> 22.532231 | D26: =+D25/8 -> 27.804087 | E26: =+E25/$E$36 -> 7.7033846 | I26: =+I25 -> 39861 | J26: =+J25 -> 39924
C30: Recursos
D31: SRUM MASTER | E31: 1
D32: MEMBER | E32: 6
D33: MEMBER | E33: 6
D34: MEMBER | E34: 2
D35: PRODUCT OWNER | E35: 1
C36: Esfuerzo Diario Disponible | E36: =SUM(E31:E34) -> 15

Sheet analisiscostos 2
C2: COSTOS HORAS =150hs/mes | T2: Rol / Seniority | U2: factor
C3: Rol / Seniority | D3: Tr | E3: Jr | F3: SSr | G3: Sr | H3: SC | I3: FR | T3: Tr | U3: 4
C4: Desarrollo | D4: 15 | E4: 17.7 | F4: 26.6 | G4: 32 | H4: 40 | I4: 30 | L4: Hora Venta | M4: =60 -> 60 | T4: Jr | U4: 2
C5: Analista | D5: 15 | E5: 17.7 | F5: 26.6 | G5: 32 | H5: 40 | L5: Hora Costo | M5: =+L34/P34 -> 23.565734 | T5: SSr | U5: 1
C6: Testing | D6: 15 | E6: 17.7 | F6: 26.6 | G6: 32 | H6: 30 | L6: Margen Màx Hs | M6: =+M4/M5-1 -> 1.5460697 | T6: Sr | U6: 0.8
C7: PM | F7: 40 | G7: 40 | H7: 40 | T7: SC | U7: 1
L8: Proyecto Venta | N8: =+L35 -> 90000 | T8: FR | U8: 1
L9: Proyecto Costo max | N9: =+L34 -> 48622
L10: Margen Min | N10: =+N8/N9-1 -> 0.85101394
L11: Margen Max | N11: =+N8/J34-1 -> 0.96453362
L13: en color verde para carga
C17: ESTIMACION INICIAL - TEMPORIZACION
D18: HS Estimada | E18: Personas | F18: Afectac | G18: semanas | H18: Hs Hombre | I18: Hs produc | J18: full ?s/ relocacion
C19: Analisis | D19: 139 | E19: 1 | F19: 1 | G19: =+D19/35/E19*(1/F19) -> 3.9714286 | H19: =+(ROUNDDOWN(G19,0)+1)*(40*E19)*(F19) -> 160 | I19: =+H19/40*35 -> 140 | J19: =+$G$23*(35*F19)*E19 -> 509.42708
C20: Desarrollo | D20: 977 | E20: 3 | F20: 0.8 | G20: =+D20/35/E20*(1/F20) -> 11.630952 | H20: =+(ROUNDDOWN(G20,0)+1)*(40*E20)*(F20) -> 1152 | I20: =+H20/40*35 -> 1008 | J20: =+$G$23*(35*F20)*E20 -> 1222.625
C21: Testing | D21: 230 | E21: 2 | F21: 1 | G21: =+D21/35/E21*(1/F21) -> 3.2857143 | H21: =+(ROUNDDOWN(G21,0)+1)*(40*E21)*(F21) -> 320 | I21: =+H21/40*35 -> 280 | J21: =+I21 -> 280
C22: PM | D22: 154 | E22: 1 | F22: 1 | G22: =+D22/35/E22*(1/F22) -> 4.4 | H22: =+(ROUNDDOWN(G22,0)+1)*(40*E22)*(F22) -> 200 | I22: =+H22/40*35 -> 175 | J22: =+$G$23*(35*F22)*E22 -> 509.42708
C23: Total Estimado | D23: =SUM(D19:D22) -> 1500 | E23: =SUM(E19:E22) -> 7 | G23: =AVERAGE(G19:G22)*2.5 -> 14.55506 | H23: =SUM(H19:H22) -> 1832 | I23: =SUM(I19:I22) -> 1603 | J23: =SUM(J19:J22) -> 2521.4792
C25: ESTIMACION INICIAL - ASIGNACIONES
D26: Sr | E26: costo Hs | F26: factor sr | G26: % tarea distrib | H26: hs asig | I26: hs esperadas | J26: Total est $ | L26: Costo real | M26: Afectac | N26: semanas | O26: Hs Hombre | P26: Hs produc
C27: Analista 1 | D27: SSr | E27: =+HLOOKUP(D27,$D$3:$I$8,3,0) -> 26.6 | F27: =VLOOKUP(D27,$T$3:$U$8,2,0) -> 1 | G27: 1 | H27: =+D19 -> 139 | I27: =+H27*F27 -> 139 | J27: =+I27*E27 -> 3697.4 | L27: =+P27*E27 -> 3724 | M27: =+F19 -> 1 | N27: =+I27/35/1*(1/M27) -> 3.9714286 | O27: =+(ROUNDDOWN(N27,0)+1)*(40*1)*(M27) -> 160 | P27: =+O27/40*35 -> 140
C28: Desarrollo 1 | D28: SSr | E28: =+HLOOKUP(D28,$D$3:$I$8,2,0) -> 26.6 | F28: =VLOOKUP(D28,$T$3:$U$8,2,0) -> 1 | G28: 0.5 | H28: =+$D$20*G28 -> 488.5 | I28: =+H28*F28 -> 488.5 | J28: =+I28*E28 -> 12994.1 | L28: =+P28*E28 -> 13406.4 | M28: =+$F$20 -> 0.8 | N28: =+I28/35/1*(1/M28) -> 17.446429 | O28: =+(ROUNDDOWN(N28,0)+1)*(40*1)*(M28) -> 576 | P28: =+O28/40*35 -> 504
C29: Desarrollo 2 | D29: Jr | E29: =+HLOOKUP(D29,$D$3:$I$8,2,0) -> 17.7 | F29: =VLOOKUP(D29,$T$3:$U$8,2,0) -> 2 | G29: 0.25 | H29: =+$D$20*G29 -> 244.25 | I29: =+H29*F29 -> 488.5 | J29: =+I29*E29 -> 8646.45 | L29: =+P29*E29 -> 8920.8 | M29: =+$F$20 -> 0.8 | N29: =+I29/35/1*(1/M29) -> 17.446429 | O29: =+(ROUNDDOWN(N29,0)+1)*(40*1)*(M29) -> 576 | P29: =+O29/40*35 -> 504
C30: Desarrollo 3 | D30: Jr | E30: =+HLOOKUP(D30,$D$3:$I$8,2,0) -> 17.7 | F30: =VLOOKUP(D30,$T$3:$U$8,2,0) -> 2 | G30: 0.25 | H30: =+$D$20*G30 -> 244.25 | I30: =+H30*F30 -> 488.5 | J30: =+I30*E30 -> 8646.45 | L30: =+P30*E30 -> 8920.8 | M30: =+$F$20 -> 0.8 | N30: =+I30/35/1*(1/M30) -> 17.446429 | O30: =+(ROUNDDOWN(N30,0)+1)*(40*1)*(M30) -> 576 | P30: =+O30/40*35 -> 504
C31: Testing 1 | D31: SC | E31: =+HLOOKUP(D31,$D$3:$I$8,4,0) -> 30 | F31: =VLOOKUP(D31,$T$3:$U$8,2,0) -> 1 | G31: 0.5 | H31: =+$D$21*G31 -> 115 | I31: =+H31*F31 -> 115 | J31: =+I31*E31 -> 3450 | L31: =+P31*E31 -> 4200 | M31: 1 | N31: =+I31/35/1*(1/M31) -> 3.2857143 | O31: =+(ROUNDDOWN(N31,0)+1)*(40*1)*(M31) -> 160 | P31: =+O31/40*35 -> 140
C32: Testing 2 | D32: SC | E32: =IFERROR(HLOOKUP(D32,$D$3:$I$8,4,0),0) -> 30 | F32: =VLOOKUP(D32,$T$3:$U$8,2,0) -> 1 | G32: 0.5 | H32: =+$D$21*G32 -> 115 | I32: =+H32*F32 -> 115 | J32: =+I32*E32 -> 3450 | L32: =+P32*E32 -> 4200 | M32: 1 | N32: =IFERROR(I32/35/1*(1/M32),0) -> 3.2857143 | O32: =+(ROUNDDOWN(N32,0)+1)*(40*1)*(M32) -> 160 | P32: =+O32/40*35 -> 140
C33: PM 1 | D33: Sr | E33: =+HLOOKUP(D33,$D$3:$I$8,5,0) -> 40 | F33: =VLOOKUP(D33,$T$3:$U$8,2,0) -> 0.8 | G33: 0.25 | H33: =+D22 -> 154 | I33: =+H33*F33 -> 123.2 | J33: =+I33*E33 -> 4928 | L33: =+P33*E33 -> 5250 | M33: 0.25 | N33: =+I33/35/1*(1/M33) -> 14.08 | O33: =+(ROUNDDOWN(N33,0)+1)*(40*1)*(M33) -> 150 | P33: =+O33/40*35 -> 131.25
E34: =+J34/D23 -> 30.5416 | F34: =AVERAGE(F27:F33) -> 1.2571429 | H34: =SUM(H27:H33) -> 1500 | I34: =SUM(I27:I33) -> 1957.7 | J34: =SUM(J27:J33) -> 45812.4 | L34: =SUM(L27:L33) -> 48622 | N34: =(G23*P34/I23)*(1+(1-(AVERAGE(M27:M33)))) -> 22.347078 | O34: =SUM(O27:O33) -> 2358 | P34: =SUM(P27:P33) -> 2063.25
J35: =+$D$23*$M$4 -> 90000 | L35: =+$D$23* $M$4 -> 90000
J36: =+J35/J34-1 -> 0.96453362 | L36: =+L35/L34-1 -> 0.85101394
N37: =+N34/4 -> 5.5867696 | O37: MESES
C38: PLAN DESARROLLO | D38: SR | E38: HS | F38: BUFFER
C39: Analista 1 | D39: =+D27 -> SSr | E39: =+E27 -> 26.6 | F39: 0.3
C40: Desarrollo 1 | D40: =+D28 -> SSr | E40: =+E28 -> 26.6 | F40: 0.3 | L40: =+L35/N37 -> 16109.488 | M40: $/MES
C41: Desarrollo 2 | D41: =+D29 -> Jr | E41: =+E29 -> 17.7 | F41: 0.3
C42: Testing 1 | D42: =+D32 -> SC | E42: =+E32 -> 30 | F42: 0.3
C43: PM 1 | D43: =+D33 -> Sr | E43: =+E33 -> 40 | F43: 0.3
F44: =AVERAGE(F39:F43) -> 0.3
C47: PLAN | D47: Hs | E47: $ | F47: HS PM AJUS | J47: Resumen | L47: HS | M47: COSTO HS | N47: COSTO EST
C48: PLAN DESARROLLO | D48: =+D23*(1-F44) -> 1050 | E48: =+D48*$M$5 -> 24744.02 | F48: =+D48*$F$34 -> 1320 | G48: =F48/+$P$34 -> 0.63976736 | J48: ESTIMACION INICIAL | L48: =+D23 -> 1500 | M48: 40 | N48: =+D23*M48 -> 60000
...

Sheet analisiscostos1
C2: COSTOS HORAS =150hs/mes
C3: Rol / Seniority | D3: Tr | E3: Jr | F3: SSr | G3: Sr | H3: SubContrato | I3: FreeLance
C4: Desarrollo | D4: 15 | E4: 25 | F4: 40 | G4: 50 | H4: 55 | I4: 25 | L4: Hora Venta | M4: =18*4.3 -> 77.4
C5: Analista | D5: 15 | E5: 25 | F5: 45 | G5: 50 | L5: Hora Costo | M5: =+G32/I23 -> 39.583333
C6: Testing | D6: 15 | E6: 25 | F6: 40 | G6: 50 | H6: 40 | L6: Margen Màx Hs | M6: =+M4/M5-1 -> 0.95536842
C7: PM | F7: 45 | G7: 50 | H7: 80
L8: Proyecto Venta | N8: =+G33 -> 23220
L9: Proyecto Costo max | N9: =+G32 -> 16625
L10: Margen Min | N10: =+N8/N9-1 -> 0.39669173
L11: Margen Max | N11: =+N8/F32-1 -> 0.94716981
L13: en color verde para carga
C17: ESTIMACION INICIAL
D18: HS Estimada | E18: Personas | F18: Afectac | G18: semanas | H18: Hs Hombre | I18: Hs produc | L18: ejemplos de proyectos
C19: Analisis | D19: 45 | E19: 1 | F19: 1 | G19: =+D19/35/E19*(1/F19) -> 1.2857143 | H19: =+(ROUNDDOWN(G19,0)+1)*(40*E19)*(F19) -> 80 | I19: =+H19/40*35 -> 70 | L19: 30 | M19: 45 | N19: 65 | O19: 80
C20: Desarrollo | D20: 150 | E20: 2 | F20: 1 | G20: =+D20/35/E20*(1/F20) -> 2.1428571 | H20: =+(ROUNDDOWN(G20,0)+1)*(40*E20)*(F20) -> 240 | I20: =+H20/40*35 -> 210 | L20: 100 | M20: 150 | N20: 205 | O20: 500
C21: Testing | D21: 45 | E21: 1 | F21: 1 | G21: =+D21/35/E21*(1/F21) -> 1.2857143 | H21: =+(ROUNDDOWN(G21,0)+1)*(40*E21)*(F21) -> 80 | I21: =+H21/40*35 -> 70 | L21: 30 | M21: 45 | N21: 65 | O21: 80
C22: PM | D22: 60 | E22: 1 | F22: 0.5 | G22: =+D22/35/E22*(1/F22) -> 3.4285714 | H22: =+(ROUNDDOWN(G22,0)+1)*(40*E22)*(F22) -> 80 | I22: =+H22/40*35 -> 70 | L22: 30 | M22: 60 | N22: 65 | O22: 100
C23: Total Estimado hs | D23: 300 | E23: =SUM(E19:E22) -> 5 | G23: =AVERAGE(G19:G22)*2.5 -> 5.0892857 | H23: =SUM(H19:H22) -> 480 | I23: =SUM(I19:I22) -> 420 | L23: 190 | M23: 300 | N23: =SUM(N19:N22) -> 400 | O23: 760
C25: ESTIMACION INICIAL
C26: Estimado | D26: Sr | E26: costo Hs | F26: Total $ | G26: Costo real | H26: S1 hs | J26: S2 | L26: S3 | N26: S4 | P26: S5
C27: Analista 1 | D27: Sr | E27: =+G5 -> 50 | F27: =+E27*D19 -> 2250 | G27: =+E27*I19 -> 3500 | H27: 30 | I27: =+H27* $E27 -> 1500 | J27: 15 | K27: =+J27* $E27 -> 750 | M27: =+L27* $E27 -> 0 | O27: =+N27* $E27 -> 0 | Q27: =+P27* $E27 -> 0
C28: Desarrollo 1 | D28: SSr | E28: =+F4 -> 40 | F28: =+D20/2*E28 -> 3000 | G28: =+E28/2*I20 -> 4200 | H28: 10 | I28: =+H28* $E28 -> 400 | J28: 20 | K28: =+J28* $E28 -> 800 | L28: 30 | M28: =+L28* $E28 -> 1200 | N28: 10 | O28: =+N28* $E28 -> 400 | P28: 5 | Q28: =+P28* $E28 -> 200
C29: Desarrollo 2 | D29: Jr | E29: =+E4 -> 25 | F29: =+D20/2* E29 -> 1875 | G29: =+E29/2*I20 -> 2625 | H29: 10 | I29: =+H29* $E29 -> 250 | J29: 20 | K29: =+J29* $E29 -> 500 | L29: 30 | M29: =+L29* $E29 -> 750 | N29: 10 | O29: =+N29* $E29 -> 250 | P29: 5 | Q29: =+P29* $E29 -> 125
C30: Testing 1 | D30: SC | E30: =+H6 -> 40 | F30: =+D21* E30 -> 1800 | G30: =+E30*I21 -> 2800 | I30: =+H30* $E30 -> 0 | K30: =+J30* $E30 -> 0 | M30: =+L30* $E30 -> 0 | N30: 30 | O30: =+N30* $E30 -> 1200 | P30: 15 | Q30: =+P30* $E30 -> 600
C31: PM 1 | D31: Sr | E31: =+G7 -> 50 | F31: =+D22* E31 -> 3000 | G31: =+E31*I22 -> 3500 | H31: =60/5 -> 12 | I31: =+H31* $E31 -> 600 | J31: 12 | K31: =+J31* $E31 -> 600 | L31: 12 | M31: =+L31* $E31 -> 600 | N31: 12 | O31: =+N31* $E31 -> 600 | P31: 12 | Q31: =+P31* $E31 -> 600
E32: =+F32/D23 -> 39.75 | F32: =SUM(F27:F31) -> 11925 | G32: =SUM(G27:G31) -> 16625 | H32: =SUM(H27:H31) -> 62 | I32: =SUM(I27:I31) -> 2750 | J32: =SUM(J27:J31) -> 67 | K32: =SUM(K27:K31) -> 2650 | L32: =SUM(L27:L31) -> 72 | M32: =SUM(M27:M31) -> 2550 | ... Q32: =SUM(Q27:Q31) -> 1525
F33: =+$D$23*$M$4 -> 23220 | G33: =+$D$23* $M$4 -> 23220
F34: =+F33/F32-1 -> 0.94716981 | G34: =+G33/G32-1 -> 0.39669173
C36: PLAN DESARROLLO | D36: SR | E36: HS | F36: BUFFER | H36: S1 | J36: S2 | L36: S3 | N36: S4 | P36: S5
C37: Analista 1 | D37: Sr | E37: 65 | F37: 0.3 | H37: =+H27-H27*$F37 -> 21 | I37: =+H37* $E37 -> 1365 | J37: =+J27-J27*$F37 -> 10.5 | K37: =+J37* $E37 -> 682.5 | L37: =+L27-L27*$F37 -> 0 | M37: =+L37* $E37 -> 0 | N37: =+N27-N27*$F37 -> 0 | O37: =+N37* $E37 -> 0 | P37: =+P27-P27*$F37 -> 0 | Q37: =+P37* $E37 -> 0
C38: Desarrollo 1 | D38: SSr | E38: 40 | F38: 0.3 | H38: =+H28-H28*$F38 -> 7 | I38: =+H38* $E38 -> 280 | J38: =+J28-J28*$F38 -> 14 | K38: =+J38* $E38 -> 560 | L38: =+L28-L28*$F38 -> 21 | M38: =+L38* $E38 -> 840 | N38: =+N28-N28*$F38 -> 7 | O38: =+N38* $E38 -> 280 | P38: =+P28-P28*$F38 -> 3.5 | Q38: =+P38* $E38 -> 140
C39: Desarrollo 2 | D39: Jr | E39: 25 | F39: 0.3 | H39: =+H29-H29*$F39 -> 7 | I39: =+H39* $E39 -> 175 | J39: =+J29-J29*$F39 -> 14 | K39: =+J39* $E39 -> 350 | L39: =+L29-L29*$F39 -> 21 | M39: =+L39* $E39 -> 525 | N39: =+N29-N29*$F39 -> 7 | O39: =+N39* $E39 -> 175 | P39: =+P29-P29*$F39 -> 3.5 | Q39: =+P39* $E39 -> 87.5
C40: Testing 1 | D40: SC | E40: 40 | F40: 0.3 | H40: =+H30-H30*$F40 -> 0 | I40: =+H40* $E40 -> 0 | J40: =+J30-J30*$F40 -> 0 | K40: =+J40* $E40 -> 0 | L40: =+L30-L30*$F40 -> 0 | M40: =+L40* $E40 -> 0 | N40: =+N30-N30*$F40 -> 21 | O40: =+N40* $E40 -> 840 | P40: =+P30-P30*$F40 -> 10.5 | Q40: =+P40* $E40 -> 420
C41: PM 1 | D41: Sr | E41: 70 | F41: 0.3 | H41: =+H31-H31*$F41 -> 8.4 | I41: =+H41* $E41 -> 588 | J41: =+J31-J31*$F41 -> 8.4 | K41: =+J41* $E41 -> 588 | L41: =+L31-L31*$F41 -> 8.4 | M41: =+L41* $E41 -> 588 | N41: =+N31-N31*$F41 -> 8.4 | O41: =+N41* $E41 -> 588 | P41: =+P31-P31*$F41 -> 8.4 | Q41: =+P41* $E41 -> 588
F42: =AVERAGE(F37:F41) -> 0.3 | H42: =SUM(H37:H41) -> 43.4 | I42: =SUM(I37:I41) -> 2408 | J42: =SUM(J37:J41) -> 46.9 | K42: =SUM(K37:K41) -> 2180.5 | L42: =SUM(L37:L41) -> 50.4 | M42: =SUM(M37:M41) -> 1953 | N42: =SUM(N37:N41) -> 43.4 | O42: =SUM(O37:O41) -> 1883 | ... Q42: =SUM(Q37:Q41) -> 1235.5
C45: PLAN | D45: Hs | E45: $
C46: PLAN DESARROLLO | D46: =+D23*(1-F42) -> 210 | E46: =+D46*$M$5 -> 8312.5
C47: BUFFER PRIMARIO PM | D47: =+(D23-D46)*0.7 -> 63 | E47: =+D47*$M$5 -> 2493.75
C48: BUFFER SECUNDA PM | D48: =+D23-D47-D46 -> 27 | E48: =+D48*$M$5 -> 1068.75
C49: BUFFER CRITICO | D49: =+I23-D23 -> 120 | E49: =+D49*$M$5 -> 4750
...

Sheet Sheet3
D11: ESTIMACION INICIAL - ASIGNACIONES
E12: Sr | F12: hs esperadas | G12: Total est $ | H12: semanas | I12: Hs Hombre | J12: Hs produc | K12: Costo real
D13: Analista 1 | E13: SSr | F13: 45 | G13: 2025 | H13: 1.2857143 | I13: 80 | J13: 70 | K13: 3150
D14: Desarrollo 1 | E14: SSr | F14: 99 | G14: 3762 | H14: 2.8285714 | I14: 120 | J14: 105 | K14: 3990
D15: Desarrollo 2 | E15: Jr | F15: 102 | G15: 2550 | H15: 2.9142857 | I15: 120 | J15: 105 | K15: 2625
D16: Testing 1 | E16: SC | F16: 45 | G16: 1800 | H16: 1.2857143 | I16: 80 | J16: 70 | K16: 2800
D17: PM 1 | E17: Sr | F17: 48 | G17: 2400 | H17: 2.7428571 | I17: 60 | J17: 52.5 | K17: 2625
F18: 339 | G18: 12537 | H18: 5.5285714 | I18: 460 | J18: 402.5 | K18: 15190
D25: ESTIMACION INICIAL - ASIGNACIONES
E26: Sr | F26: % Tarea distribuida | G26: Afectación Horaria
D27: Analista 1 | E27: SSr | F27: 1 | G27: 1
D28: Desarrollo 1 | E28: SSr | F28: 0.5 | G28: 0.8
D29: Desarrollo 2 | E29: Jr | F29: 0.25 | G29: 0.8
D30: Desarrollo 3 | E30: Jr | F30: 0.25 | G30: 0.8
D31: Testing 1 | E31: SC | F31: 0.5 | G31: 1
D32: Testing 2 | E32: SC | F32: 0.5 | G32: 1
D33: PM 1 | E33: Sr | F33: 0.25 | G33: 0.25

Sheet Sheet1
E11: Analisis Ficha | F11: En Progreso
E12: Diseño Ficha | F12: En Progreso
E13: Ficha Residente | F13: En Progreso
E14: datos personales | F14: Pendiente
E15: selección silla | F15: Pendiente
E16: selección cama | F16: Pendiente
E17: direcciones | F17: Pendiente
E18: telefonos | F18: Pendiente
E19: facturación | F19: Pendiente
E20: Testing Ficha Iter 1 solo 50% | F20: Pendiente
E21: Analisis Espera | F21: Completo
E22: Diseño Espera | F22: Completo
... E41: Administracion Proyecto | F41: En Progreso
F52: Hs produc
E53: Analista 1 | F53: 140
E54: Desarrollo 1 | F54: 504
E55: Desarrollo 2 | F55: 504
E56: Desarrollo 3 | F56: 504
E57: Testing 1 | F57: 140
E58: Testing 2 | F58: 140
E59: PM 1 | F59: 131.25
F60: 2063.25
